<!DOCTYPE html>
<html>
<head>
    <meta charset="UTF-8" />
    <title>Utilizing JavaScript Exception Handling</title>
</head>

<body>  
    <button onclick="simpleTryCatch();">Simple Try Catch</button>
    <script>
        function simpleTryCatch() {
            let result;

            try {
                result = x / 10;
            } catch (error) {
                // A JS Error object always has 'name' and 'message' properties, and passes it into the catch block
                console.log(error.message);
            }
        }
    </script>

    <button onclick="finallyCatchSample();">Finally Catch Sample</button>
    <script>
        function finallyCatchSample() {
            let result;

            try {
                console.log("An error will occur.");
                result = x / 10;
                console.log("This line will never run.");// once there is an error in previous line
            } catch (error) {
                console.log("In the 'Catch' block: " + error.message);
            }
            finally {
                console.log("In the 'finally' block");// always will run if there is an error
            }
        }
    </script> 
    
    <button onclick="finallySuccessSample();">Finally Success Sample</button>
    <script>
        function finallySuccessSample() {
            let result;
            let x = 100;

            try {
                console.log("An error won't occur.");
                result = x / 10;
            } catch (error) {
                console.log("In the 'Catch' block: " + error.message);
            }
            finally {
                console.log("In the 'finally' block");// always will run if there is an error
            }
        }
    </script>  

<button onclick="throwError();">Throw Error</button>
<script>
    function throwError() {
        try {
            attemptDivision();
        } catch (error) {
            console.log(error.message + " - Error Type: " + error.name);
        }
    }

    function attemptDivision() {
            let result;
            try {
                result = x / 10;
            } catch (error) {
                // Always include at least a 'message' and 'name' properties
            throw {
                "message": "In the attemptDivision() method the following error occured: " + error.message,
                "name": "CustomError"
            };
        }
    }
</script>  
</body>